-- Logs begin at Sat 2018-12-01 20:47:10 UTC, end at Wed 2018-12-05 15:00:01 UTC. --
Dec 01 22:07:12 ip-172-31-40-200 systemd[1]: Started gunicorn daemon.
Dec 01 22:07:13 ip-172-31-40-200 gunicorn[20925]: [2018-12-01 22:07:13 +0000] [20925] [INFO] Starting gunicorn 19.9.0
Dec 01 22:07:13 ip-172-31-40-200 gunicorn[20925]: [2018-12-01 22:07:13 +0000] [20925] [INFO] Listening at: unix:/home/ubuntu/howrah_express/jain_deemed.sock (20925)
Dec 01 22:07:13 ip-172-31-40-200 gunicorn[20925]: [2018-12-01 22:07:13 +0000] [20925] [INFO] Using worker: sync
Dec 01 22:07:13 ip-172-31-40-200 gunicorn[20925]: [2018-12-01 22:07:13 +0000] [20966] [INFO] Booting worker with pid: 20966
Dec 01 22:07:13 ip-172-31-40-200 gunicorn[20925]: [2018-12-01 22:07:13 +0000] [20966] [ERROR] Exception in worker process
Dec 01 22:07:13 ip-172-31-40-200 gunicorn[20925]: Traceback (most recent call last):
Dec 01 22:07:13 ip-172-31-40-200 gunicorn[20925]:   File "/home/ubuntu/howrah_express/venv/lib/python3.6/site-packages/gunicorn/arbiter.py", line 583, in spawn_worker
Dec 01 22:07:13 ip-172-31-40-200 gunicorn[20925]:     worker.init_process()
Dec 01 22:07:13 ip-172-31-40-200 gunicorn[20925]:   File "/home/ubuntu/howrah_express/venv/lib/python3.6/site-packages/gunicorn/workers/base.py", line 129, in init_process
Dec 01 22:07:13 ip-172-31-40-200 gunicorn[20925]:     self.load_wsgi()
Dec 01 22:07:13 ip-172-31-40-200 gunicorn[20925]:   File "/home/ubuntu/howrah_express/venv/lib/python3.6/site-packages/gunicorn/workers/base.py", line 138, in load_wsgi
Dec 01 22:07:13 ip-172-31-40-200 gunicorn[20925]:     self.wsgi = self.app.wsgi()
Dec 01 22:07:13 ip-172-31-40-200 gunicorn[20925]:   File "/home/ubuntu/howrah_express/venv/lib/python3.6/site-packages/gunicorn/app/base.py", line 67, in wsgi
Dec 01 22:07:13 ip-172-31-40-200 gunicorn[20925]:     self.callable = self.load()
Dec 01 22:07:13 ip-172-31-40-200 gunicorn[20925]:   File "/home/ubuntu/howrah_express/venv/lib/python3.6/site-packages/gunicorn/app/wsgiapp.py", line 52, in load
Dec 01 22:07:13 ip-172-31-40-200 gunicorn[20925]:     return self.load_wsgiapp()
Dec 01 22:07:13 ip-172-31-40-200 gunicorn[20925]:   File "/home/ubuntu/howrah_express/venv/lib/python3.6/site-packages/gunicorn/app/wsgiapp.py", line 41, in load_wsgiapp
Dec 01 22:07:13 ip-172-31-40-200 gunicorn[20925]:     return util.import_app(self.app_uri)
Dec 01 22:07:13 ip-172-31-40-200 gunicorn[20925]:   File "/home/ubuntu/howrah_express/venv/lib/python3.6/site-packages/gunicorn/util.py", line 350, in import_app
Dec 01 22:07:13 ip-172-31-40-200 gunicorn[20925]:     __import__(module)
Dec 01 22:07:13 ip-172-31-40-200 gunicorn[20925]: ModuleNotFoundError: No module named 'jain_deemed.wsgi'
Dec 01 22:07:13 ip-172-31-40-200 gunicorn[20925]: [2018-12-01 22:07:13 +0000] [20966] [INFO] Worker exiting (pid: 20966)
Dec 01 22:07:13 ip-172-31-40-200 gunicorn[20925]: [2018-12-01 22:07:13 +0000] [20968] [INFO] Booting worker with pid: 20968
Dec 01 22:07:13 ip-172-31-40-200 gunicorn[20925]: [2018-12-01 22:07:13 +0000] [20968] [ERROR] Exception in worker process
Dec 01 22:07:13 ip-172-31-40-200 gunicorn[20925]: Traceback (most recent call last):
Dec 01 22:07:13 ip-172-31-40-200 gunicorn[20925]:   File "/home/ubuntu/howrah_express/venv/lib/python3.6/site-packages/gunicorn/arbiter.py", line 583, in spawn_worker
Dec 01 22:07:13 ip-172-31-40-200 gunicorn[20925]:     worker.init_process()
Dec 01 22:07:13 ip-172-31-40-200 gunicorn[20925]:   File "/home/ubuntu/howrah_express/venv/lib/python3.6/site-packages/gunicorn/workers/base.py", line 129, in init_process
Dec 01 22:07:13 ip-172-31-40-200 gunicorn[20925]:     self.load_wsgi()
Dec 01 22:07:13 ip-172-31-40-200 gunicorn[20925]:   File "/home/ubuntu/howrah_express/venv/lib/python3.6/site-packages/gunicorn/workers/base.py", line 138, in load_wsgi
Dec 01 22:07:13 ip-172-31-40-200 gunicorn[20925]:     self.wsgi = self.app.wsgi()
Dec 01 22:07:13 ip-172-31-40-200 gunicorn[20925]:   File "/home/ubuntu/howrah_express/venv/lib/python3.6/site-packages/gunicorn/app/base.py", line 67, in wsgi
Dec 01 22:07:13 ip-172-31-40-200 gunicorn[20925]:     self.callable = self.load()
Dec 01 22:07:13 ip-172-31-40-200 gunicorn[20925]:   File "/home/ubuntu/howrah_express/venv/lib/python3.6/site-packages/gunicorn/app/wsgiapp.py", line 52, in load
Dec 01 22:07:13 ip-172-31-40-200 gunicorn[20925]:     return self.load_wsgiapp()
Dec 01 22:07:13 ip-172-31-40-200 gunicorn[20925]:   File "/home/ubuntu/howrah_express/venv/lib/python3.6/site-packages/gunicorn/app/wsgiapp.py", line 41, in load_wsgiapp
Dec 01 22:07:13 ip-172-31-40-200 gunicorn[20925]:     return util.import_app(self.app_uri)
Dec 01 22:07:13 ip-172-31-40-200 gunicorn[20925]:   File "/home/ubuntu/howrah_express/venv/lib/python3.6/site-packages/gunicorn/util.py", line 350, in import_app
Dec 01 22:07:13 ip-172-31-40-200 gunicorn[20925]:     __import__(module)
Dec 01 22:07:13 ip-172-31-40-200 gunicorn[20925]: ModuleNotFoundError: No module named 'jain_deemed.wsgi'
Dec 01 22:07:13 ip-172-31-40-200 gunicorn[20925]: [2018-12-01 22:07:13 +0000] [20968] [INFO] Worker exiting (pid: 20968)
Dec 01 22:07:13 ip-172-31-40-200 gunicorn[20925]: Traceback (most recent call last):
Dec 01 22:07:13 ip-172-31-40-200 gunicorn[20925]:   File "/home/ubuntu/howrah_express/venv/lib/python3.6/site-packages/gunicorn/arbiter.py", line 203, in run
Dec 01 22:07:13 ip-172-31-40-200 gunicorn[20925]:     self.manage_workers()
Dec 01 22:07:13 ip-172-31-40-200 gunicorn[20925]:   File "/home/ubuntu/howrah_express/venv/lib/python3.6/site-packages/gunicorn/arbiter.py", line 545, in manage_workers
Dec 01 22:07:13 ip-172-31-40-200 gunicorn[20925]:     self.spawn_workers()
Dec 01 22:07:13 ip-172-31-40-200 gunicorn[20925]:   File "/home/ubuntu/howrah_express/venv/lib/python3.6/site-packages/gunicorn/arbiter.py", line 617, in spawn_workers
Dec 01 22:07:13 ip-172-31-40-200 gunicorn[20925]:     time.sleep(0.1 * random.random())
Dec 01 22:07:13 ip-172-31-40-200 gunicorn[20925]:   File "/home/ubuntu/howrah_express/venv/lib/python3.6/site-packages/gunicorn/arbiter.py", line 245, in handle_chld
Dec 01 22:07:13 ip-172-31-40-200 gunicorn[20925]:     self.reap_workers()
Dec 01 22:07:13 ip-172-31-40-200 gunicorn[20925]:   File "/home/ubuntu/howrah_express/venv/lib/python3.6/site-packages/gunicorn/arbiter.py", line 525, in reap_workers
Dec 01 22:07:13 ip-172-31-40-200 gunicorn[20925]:     raise HaltServer(reason, self.WORKER_BOOT_ERROR)
Dec 01 22:07:13 ip-172-31-40-200 gunicorn[20925]: gunicorn.errors.HaltServer: <HaltServer 'Worker failed to boot.' 3>
Dec 01 22:07:13 ip-172-31-40-200 gunicorn[20925]: During handling of the above exception, another exception occurred:
Dec 01 22:07:13 ip-172-31-40-200 gunicorn[20925]: Traceback (most recent call last):
Dec 01 22:07:13 ip-172-31-40-200 gunicorn[20925]:   File "/home/ubuntu/howrah_express/venv/bin/gunicorn", line 11, in <module>
Dec 01 22:07:13 ip-172-31-40-200 gunicorn[20925]:     sys.exit(run())
Dec 01 22:07:13 ip-172-31-40-200 gunicorn[20925]:   File "/home/ubuntu/howrah_express/venv/lib/python3.6/site-packages/gunicorn/app/wsgiapp.py", line 61, in run
Dec 01 22:07:13 ip-172-31-40-200 gunicorn[20925]:     WSGIApplication("%(prog)s [OPTIONS] [APP_MODULE]").run()
Dec 01 22:07:13 ip-172-31-40-200 gunicorn[20925]:   File "/home/ubuntu/howrah_express/venv/lib/python3.6/site-packages/gunicorn/app/base.py", line 223, in run
Dec 01 22:07:13 ip-172-31-40-200 gunicorn[20925]:     super(Application, self).run()
Dec 01 22:07:13 ip-172-31-40-200 gunicorn[20925]:   File "/home/ubuntu/howrah_express/venv/lib/python3.6/site-packages/gunicorn/app/base.py", line 72, in run
Dec 01 22:07:13 ip-172-31-40-200 gunicorn[20925]:     Arbiter(self).run()
Dec 01 22:07:13 ip-172-31-40-200 gunicorn[20925]:   File "/home/ubuntu/howrah_express/venv/lib/python3.6/site-packages/gunicorn/arbiter.py", line 232, in run
Dec 01 22:07:13 ip-172-31-40-200 gunicorn[20925]:     self.halt(reason=inst.reason, exit_status=inst.exit_status)
Dec 01 22:07:13 ip-172-31-40-200 gunicorn[20925]:   File "/home/ubuntu/howrah_express/venv/lib/python3.6/site-packages/gunicorn/arbiter.py", line 345, in halt
Dec 01 22:07:13 ip-172-31-40-200 gunicorn[20925]:     self.stop()
